Workbook

Sheet Formulas
A1: Family | B1: Formula | C1: Result
A2: Math | B2: =SUM(Data!A1:A20) | C2: =SUM(Data!A1:A20)
A3: Math | B3: =SUMIF(Data!A1:A20,">10") | C3: =SUMIF(Data!A1:A20,">10")
A4: Math | B4: =SUMIFS(Data!A1:A20,Data!A1:A20,">5",Data!A1:A20,"<15") | C4: =SUMIFS(Data!A1:A20,Data!A1:A20,">5",Data!A1:A20,"<15")
A5: Math | B5: =SUMPRODUCT(Data!A1:A5,Data!A6:A10) | C5: =SUMPRODUCT(Data!A1:A5,Data!A6:A10)
A6: Math | B6: =ROUND(PI(),2) | C6: =ROUND(PI(),2)
A7: Math | B7: =ROUNDUP(2.341,1) | C7: =ROUNDUP(2.341,1)
A8: Math | B8: =ROUNDDOWN(2.349,2) | C8: =ROUNDDOWN(2.349,2)
A9: Math | B9: =MOD(17,5) | C9: =MOD(17,5)
A10: Math | B10: =INT(-3.7) | C10: =INT(-3.7)
A11: Math | B11: =TRUNC(-3.7) | C11: =TRUNC(-3.7)
A12: Math | B12: =ABS(-5) | C12: =ABS(-5)
A13: Math | B13: =SQRT(16) | C13: =SQRT(16)
A14: Math | B14: =POWER(2,10) | C14: =POWER(2,10)
A15: Math | B15: =EXP(1) | C15: =EXP(1)
A16: Math | B16: =LN(10) | C16: =LN(10)
A17: Math | B17: =LOG(1000) | C17: =LOG(1000)
A18: Math | B18: =LOG10(100) | C18: =LOG10(100)
A19: Math | B19: =LOG(8,2) | C19: =LOG(8,2)
A20: Math | B20: =PI() | C20: =PI()
A21: Math | B21: =CEILING(4.3,1) | C21: =CEILING(4.3,1)
A22: Math | B22: =FLOOR(4.7,1) | C22: =FLOOR(4.7,1)
A23: Math | B23: =MROUND(10,3) | C23: =MROUND(10,3)
A24: Math | B24: =SIGN(-2) | C24: =SIGN(-2)
A25: Math | B25: =FACT(5) | C25: =FACT(5)
A26: Math | B26: =COMBIN(5,2) | C26: =COMBIN(5,2)
A27: Math | B27: =GCD(12,18) | C27: =GCD(12,18)
A28: Math | B28: =LCM(4,6) | C28: =LCM(4,6)
A29: Math | B29: =SUBTOTAL(9,Data!A1:A20) | C29: =SUBTOTAL(9,Data!A1:A20)
A30: Math | B30: =SUBTOTAL(1,Data!A1:A20) | C30: =SUBTOTAL(1,Data!A1:A20)
A31: Math | B31: =AGGREGATE(9,6,Data!A1:A20) | C31: =AGGREGATE(9,6,Data!A1:A20)
A32: Math | B32: =PRODUCT(1,2,3,4) | C32: =PRODUCT(1,2,3,4)
A33: Math | B33: =QUOTIENT(17,5) | C33: =QUOTIENT(17,5)
A34: Math | B34: =EVEN(3) | C34: =EVEN(3)
A35: Math | B35: =ODD(4) | C35: =ODD(4)
A36: Math | B36: =RADIANS(180) | C36: =RADIANS(180)
A37: Math | B37: =DEGREES(PI()) | C37: =DEGREES(PI())
A38: Math | B38: =SIN(PI()/2) | C38: =SIN(PI()/2)
A39: Math | B39: =COS(0) | C39: =COS(0)
A40: Math | B40: =TAN(PI()/4) | C40: =TAN(PI()/4)
...

Sheet Data
A1: 1 | B1: alpha | C1: 46037 | F1: Item | G1: Qty | H1: Price | J1: -10000 | K1: 46023
A2: 2 | B2: beta | C2: 46044 | F2: Apple | G2: 10 | H2: 0.5 | J2: 2750 | K2: 46242
A3: 3 | B3: gamma | C3: 46051 | F3: Pear | G3: 4 | H3: 0.75 | J3: 4250 | K3: 46461
A4: 4 | B4: delta | C4: 46058 | F4: Apple | G4: 7 | H4: 0.55 | J4: 3250 | K4: 46680
A5: 5 | B5: epsilon | C5: 46065 | F5: Plum | G5: 12 | H5: 0.3 | J5: 2750 | K5: 46899
A6: 6 | B6: zeta | C6: 46072 | F6: Pear | G6: 9 | H6: 0.8
A7: 7 | B7: eta | C7: 46079 | F7: Apple | G7: 3 | H7: 0.6
A8: 8 | B8: theta | C8: 46086 | F8: Fig | G8: 6 | H8: 1.2
A9: 9 | B9: iota | C9: 46093
A10: 10 | B10: kappa | C10: 46100 | F10: Item
A11: 11 | B11: alpha11 | C11: 46107 | F11: Apple
A12: 12 | B12: beta12 | C12: 46114
A13: 13 | B13: gamma13 | C13: 46121 | F13: Item
A14: 14 | B14: delta14 | C14: 46128 | F14: Fig
A15: 15 | B15: epsilon15 | C15: 46135
A16: 16 | B16: zeta16 | C16: 46142
A17: 17 | B17: eta17 | C17: 46149
A18: 18 | B18: theta18 | C18: 46156
A19: 19 | B19: iota19 | C19: 46163
A20: 20 | B20: kappa20 | C20: 46170
